File: Data/Red_20x5_25%/Spectra_Before_Cycling.txt
#Acq. time (s)=	20
#Accumulations=	5
#Range (cm-¹)=	1000...3000
#Windows=	1
#Auto scanning=	Off
#Autofocus=	Off
#Macrospot=	Off
#AutoExposure=	Off
#Spike filter=	Multiple accum.
#Delay time (s)=	0
#Binning=	1
#Readout mode=	Signal
#DeNoise=	Off
#ICS correction=	Off
#Dark correction=	Off
#Inst. Process=	Off
#Detector Gain=	Best Dynamic Range
#Detector ADC=	45 kHz
#Detector temperature (°C)=	-60.1
#Instrument=	LabRAM HR Evol
#Detector=	Syncerity OE
#Objective=	x100_VIS_LWD
#Grating=	300 (600nm)
#ND Filter=	25%
#Laser=	633nm_Edge
#Hole=	199.981
#Range=	Visible
#StageXY=	75x50mm Scan+
#StageZ=	Z motor
#X (µm)=	0
#Y (µm)=	0
#Z (µm)=	-4180.05
#Full time(mm:ss)=	1:43
#Project=
#Sample=
#Site=
#Title=	Test2_25%
#Remark=
#Date=	30.09.2024 10:52
#Acquired=	30.09.2024 10:52:24
#AxisType[0]=Intens
#AxisUnit[0]=Cnt
#AxisType[1]=Spectr
#AxisUnit[1]=1/cm
1000.82	547
1003.15	544
1005.48	557.5
1007.81	536.5
1010.14	543
1012.47	544.5
1014.8	538
1017.12	561.5
1019.45	569.5
1021.77	566.5
1024.1	564
1026.42	554
1028.74	566
1031.07	561
1033.39	577
1035.71	573
1038.03	569
1040.35	572.5
1042.66	554
1044.98	576
1047.3	581
1049.62	575
1051.93	567.5
1054.25	589.5
1056.56	576
1058.87	585.5
1061.18	584
1063.5	576.5
1065.81	577.5
1068.12	580.5
1070.43	588.5
1072.74	583
1075.04	580.5
1077.35	571.5
1079.66	593.5
1081.96	591
1084.27	575
1086.57	591.5
1088.88	590.5
1091.18	578.5
1093.48	599.5
1095.78	585
1098.08	613
1100.38	597
1102.68	590
1104.98	585
1107.28	613
1109.57	596.5
1111.87	602
1114.17	596
1116.46	603
1118.76	613
1121.05	608
1123.34	600
1125.63	622
1127.92	614
1130.21	605.5
1132.5	619
1134.79	601.5
1137.08	631.5
1139.37	637
1141.65	627.5
1143.94	607
1146.23	612
1148.51	622.5
1150.79	637
1153.08	625.5
1155.36	621
1157.64	614
1159.92	612.5
1162.2	616.5
1164.48	620
1166.76	628
1169.04	619.5
1171.32	627
1173.59	609
1175.87	620
1178.14	634
1180.42	603
1182.69	595
1184.97	623.5
1187.24	605
1189.51	622
1191.78	631
1194.05	620
1196.32	632.5
1198.59	617.5
1200.86	640.5
1203.12	622.5
1205.39	616
1207.66	625
1209.92	618
1212.19	626
1214.45	624
1216.71	616
1218.97	609.5
1221.24	625.5
1223.5	623
1225.76	625
1228.02	628.5
1230.28	629
1232.53	645.5
1234.79	616
1237.05	628
1239.3	626
1241.56	620
1243.81	625.5
1246.07	621
1248.32	621.5
1250.57	615
1252.82	613
1255.07	616.5
1257.32	624.5
1259.57	611
1261.82	634.5
1264.07	625.5
1266.32	629.5
1268.57	631
1270.81	621.5
1273.06	615.5
1275.3	623.5
1277.55	633.5
1279.79	625.5
1282.03	640.5
1284.27	611
1286.51	624
1288.75	613
1290.99	626.5
1293.23	615
1295.47	621.5
1297.71	615
1299.94	621.5
1302.18	621
1304.42	627
1306.65	639
1308.88	638
1311.12	605.5
1313.35	627.5
1315.58	634.5
1317.81	642
1320.04	649.5
1322.27	631
1324.5	653.5
1326.73	654
1328.96	641
1331.19	633.5
1333.41	629.5
1335.64	638.5
1337.86	653
1340.09	623
1342.31	651
1344.53	640
1346.75	638
1348.98	627
1351.2	633.5
1353.42	647.5
1355.64	647.5
1357.85	648
1360.07	635
1362.29	636
1364.51	639.5
1366.72	645.5
1368.94	646
1371.15	646.5
1373.36	638.5
1375.58	640.5
1377.79	645
1380	635
1382.21	651
1384.42	624
1386.63	633
1388.84	652
1391.05	638.5
1393.26	630
1395.47	644
1397.67	630.5
1399.88	639
1402.08	638
1404.29	649
1406.49	640.5
1408.69	644
1410.89	652.5
1413.09	640.5
1415.3	648
1417.5	642
1419.69	663
1421.89	641.5
1424.09	641
1426.29	647
1428.48	646.5
1430.68	646
1432.88	653
1435.07	661
1437.26	650
1439.46	657
1441.65	643.5
1443.84	659
1446.03	648.5
1448.22	670.5
1450.41	653
1452.6	649.5
1454.79	675
1456.98	647
1459.16	672
1461.35	666.5
1463.54	654
1465.72	649
1467.91	651
1470.09	658
1472.27	666.5
1474.46	648
1476.64	665
1478.82	659.5
1481	663.5
1483.18	660.5
1485.36	666.5
1487.53	674.5
1489.71	669
1491.89	684
1494.07	676.5
1496.24	677
1498.42	684.5
1500.59	686
1502.76	671
1504.94	672
1507.11	681
1509.28	665.5
1511.45	673.5
1513.62	676.5
1515.79	687.5
1517.96	688
1520.13	679
1522.29	685
1524.46	687
1526.63	678
1528.79	692.5
1530.96	692.5
1533.12	711
1535.28	688.5
1537.45	701.5
1539.61	709.5
1541.77	709
1543.93	722
1546.09	741.5
1548.25	743.5
1550.41	749
1552.57	776.5
1554.73	791
1556.88	827.5
1559.04	861.5
1561.19	890.5
1563.35	944
1565.5	1037
1567.66	1161
1569.81	1333.5
1571.96	1582.5
1574.11	1876.5
1576.26	2051.5
1578.41	1993.5
1580.56	1785
1582.71	1514.5
1584.86	1275
1587.01	1086
1589.15	987.5
1591.3	906
1593.44	853
1595.59	820
1597.73	806
1599.88	765
1602.02	763.5
1604.16	744
1606.3	733
1608.44	716.5
1610.58	709.5
1612.72	719
1614.86	716
1617	709.5
1619.14	716
1621.27	702.5
1623.41	711
1625.55	689.5
1627.68	697
1629.82	695
1631.95	691
1634.08	693
1636.21	684
1638.35	690
1640.48	710
1642.61	680
1644.74	689
1646.87	697.5
1649	684.5
1651.12	693.5
1653.25	687
1655.38	706
1657.5	700
1659.63	672.5
1661.75	682
1663.88	668
1666	691.5
1668.12	671
1670.24	668.5
1672.36	694.5
1674.48	671
1676.6	680
1678.72	676
1680.84	691
1682.96	688
1685.08	689
1687.19	681
1689.31	680
1691.43	681
1693.54	681
1695.65	688.5
1697.77	678
1699.88	667
1701.99	686.5
1704.1	702
1706.21	670
1708.32	695.5
1710.43	670
1712.54	681
1714.65	676
1716.76	667.5
1718.87	689
1720.97	677
1723.08	690.5
1725.18	679
1727.29	669
1729.39	695.5
1731.49	680.5
1733.6	694
1735.7	714.5
1737.8	697
1739.9	685.5
1742	700.5
1744.1	711.5
1746.2	709.5
1748.3	704.5
1750.39	685.5
1752.49	690
1754.59	676.5
1756.68	695
1758.78	679
1760.87	705
1762.96	701.5
1765.06	690
1767.15	686
1769.24	683.5
1771.33	702
1773.42	721
1775.51	690
1777.6	706.5
1779.69	716.5
1781.78	707.5
1783.86	713
1785.95	716.5
1788.04	703.5
1790.12	697
1792.21	691.5
1794.29	685
1796.37	705
1798.46	692.5
1800.54	711.5
1802.62	714
1804.7	688.5
1806.78	700
1808.86	703
1810.94	711.5
1813.02	695
1815.09	687.5
1817.17	699
1819.25	695
1821.32	692
1823.4	689
1825.47	688
1827.55	684
1829.62	665
1831.69	673.5
1833.77	703
1835.84	705.5
1837.91	680
1839.98	683
1842.05	695.5
1844.12	688
1846.18	673
1848.25	703
1850.32	706.5
1852.39	692.5
1854.45	697.5
1856.52	678.5
1858.58	695.5
1860.64	681.5
1862.71	693.5
1864.77	678
1866.83	681
1868.89	689
1870.95	690
1873.01	705
1875.07	696
1877.13	687
1879.19	699.5
1881.25	693
1883.31	688
1885.36	703
1887.42	683.5
1889.47	702
1891.53	694
1893.58	702.5
1895.63	703.5
1897.69	705
1899.74	703
1901.79	706.5
1903.84	696.5
1905.89	693
1907.94	687.5
1909.99	710.5
1912.04	714
1914.09	709.5
1916.13	713.5
1918.18	713.5
1920.23	694.5
1922.27	724.5
1924.32	702
1926.36	697
1928.4	712
1930.44	706.5
1932.49	698.5
1934.53	726
1936.57	718
1938.61	692.5
1940.65	708
1942.69	712
1944.73	719.5
1946.77	696
1948.8	699.5
1950.84	705.5
1952.88	699
1954.91	717.5
1956.95	700
1958.98	706.5
1961.01	692
1963.05	714.5
1965.08	695
1967.11	719.5
1969.14	718
1971.17	683.5
1973.2	709.5
1975.23	705
1977.26	696.5
1979.29	689
1981.32	705
1983.34	714
1985.37	688
1987.39	697.5
1989.42	698
1991.44	683.5
1993.47	705
1995.49	705
1997.51	700
1999.54	688
2001.56	713.5
2003.58	687
2005.6	689.5
2007.62	698.5
2009.64	691
2011.66	692
2013.67	698
2015.69	690
2017.71	685.5
2019.72	706.5
2021.74	702.5
2023.75	698
2025.77	688.5
2027.78	681
2029.79	701.5
2031.81	685
2033.82	695
2035.83	702
2037.84	695
2039.85	693.5
2041.86	701.5
2043.87	711.5
2045.87	701.5
2047.88	703
2049.89	694
2051.9	699.5
2053.9	724
2055.91	722.5
2057.91	718.5
2059.92	724
2061.92	722
2063.92	720.5
2065.92	721.5
2067.93	731
2069.93	694
2071.93	741
2073.93	725
2075.93	696
2077.92	708
2079.92	714
2081.92	727.5
2083.92	714.5
2085.91	714
2087.91	735.5
2089.9	711.5
2091.9	723.5
2093.89	705
2095.88	725
2097.88	722
2099.87	712
2101.86	721
2103.85	731.5
2105.84	708.5
2107.83	737
2109.82	717
2111.81	716
2113.8	710
2115.78	719
2117.77	713
2119.76	700.5
2121.74	719
2123.73	716.5
2125.71	716
2127.7	698
2129.68	701
2131.66	709.5
2133.64	716
2135.62	702.5
2137.61	707
2139.59	720
2141.57	713
2143.54	726
2145.52	702.5
2147.5	716
2149.48	710.5
2151.46	701
2153.43	708.5
2155.41	713
2157.38	705
2159.36	715
2161.33	710
2163.3	706.5
2165.28	688.5
2167.25	702.5
2169.22	715.5
2171.19	715.5
2173.16	733
2175.13	697
2177.1	704
2179.07	709
2181.04	711.5
2183	719
2184.97	709
2186.94	704
2188.9	708
2190.87	728
2192.83	726.5
2194.79	729
2196.76	719
2198.72	721.5
2200.68	707
2202.64	730.5
2204.61	715
2206.57	722
2208.53	722
2210.48	713
2212.44	731.5
2214.4	705
2216.36	722
2218.32	704.5
2220.27	730.5
2222.23	725.5
2224.18	738
2226.14	721
2228.09	731.5
2230.05	708
2232	731
2233.95	730.5
2235.9	681.5
2237.85	711.5
2239.8	711
2241.75	720
2243.7	719.5
2245.65	716.5
2247.6	701
2249.55	708.5
2251.5	712.5
2253.44	705
2255.39	701.5
2257.33	710
2259.28	709
2261.22	703
2263.17	687
2265.11	713.5
2267.05	712.5
2268.99	695
2270.94	707
2272.88	715.5
2274.82	708.5
2276.76	721
2278.7	679.5
2280.63	714
2282.57	717
2284.51	699.5
2286.45	717
2288.38	706
2290.32	685
2292.25	709.5
2294.19	718.5
2296.12	706
2298.06	716.5
2299.99	704.5
2301.92	708
2303.85	708
2305.78	719
2307.71	712.5
2309.64	708.5
2311.57	704.5
2313.5	701.5
2315.43	722
2317.36	720
2319.29	718.5
2321.21	716
2323.14	702
2325.06	732.5
2326.99	718
2328.91	698.5
2330.84	712
2332.76	690
2334.68	700
2336.6	689
2338.53	721
2340.45	700
2342.37	712.5
2344.29	718
2346.21	712.5
2348.13	703
2350.05	712
2351.96	720
2353.88	715
2355.8	709.5
2357.71	698
2359.63	722
2361.54	690.5
2363.46	705
2365.37	702
2367.28	713.5
2369.2	704
2371.11	717.5
2373.02	700
2374.93	715
2376.84	710.5
2378.75	707
2380.66	714.5
2382.57	691.5
2384.48	719
2386.38	715
2388.29	697
2390.2	714
2392.1	687.5
2394.01	675
2395.91	699.5
2397.82	699
2399.72	675
2401.63	704.5
2403.53	714
2405.43	690
2407.33	701.5
2409.23	694
2411.13	696
2413.03	693.5
2414.93	684
2416.83	698.5
2418.73	701
2420.63	699.5
2422.52	715
2424.42	704
2426.32	692
2428.21	710
2430.11	707.5
2432	709.5
2433.89	707.5
2435.79	697
2437.68	714
2439.57	714.5
2441.46	704
2443.35	725
2445.25	721.5
2447.13	726
2449.02	716.5
2450.91	718
2452.8	739
2454.69	747.5
2456.58	724
2458.46	733
2460.35	730
2462.23	723.5
2464.12	734
2466	722
2467.89	712
2469.77	736
2471.65	700
2473.54	723
2475.42	714.5
2477.3	725.5
2479.18	701
2481.06	718.5
2482.94	715
2484.82	711
2486.7	722
2488.57	730.5
2490.45	692
2492.33	694
2494.2	713.5
2496.08	708
2497.96	708.5
2499.83	715.5
2501.7	704
2503.58	685.5
2505.45	711
2507.32	700.5
2509.2	706.5
2511.07	702
2512.94	702
2514.81	702.5
2516.68	698.5
2518.55	704.5
2520.42	686.5
2522.28	699.5
2524.15	701
2526.02	705
2527.88	694
2529.75	710
2531.62	704
2533.48	689
2535.34	697
2537.21	706
2539.07	715
2540.94	705
2542.8	695.5
2544.66	711
2546.52	696.5
2548.38	695.5
2550.24	709.5
2552.1	687
2553.96	715.5
2555.82	700.5
2557.68	704
2559.53	702
2561.39	683
2563.25	693
2565.1	698.5
2566.96	694.5
2568.81	703
2570.67	714.5
2572.52	693.5
2574.37	701
2576.23	705.5
2578.08	711.5
2579.93	715.5
2581.78	699.5
2583.63	701.5
2585.48	727.5
2587.33	710.5
2589.18	715
2591.03	731.5
2592.87	714
2594.72	735.5
2596.57	711
2598.41	716
2600.26	741
2602.11	729.5
2603.95	754
2605.79	747.5
2607.64	761
2609.48	761
2611.32	745.5
2613.17	767.5
2615.01	773.5
2616.85	802
2618.69	778
2620.53	802
2622.37	796.5
2624.21	781
2626.04	815
2627.88	825
2629.72	797
2631.56	825.5
2633.39	813.5
2635.23	827
2637.06	823.5
2638.9	802
2640.73	820
2642.56	811.5
2644.4	838
2646.23	839.5
2648.06	824.5
2649.89	843
2651.72	829.5
2653.55	815.5
2655.38	833.5
2657.21	847
2659.04	861.5
2660.87	869
2662.7	850.5
2664.53	889.5
2666.35	887.5
2668.18	926.5
2670	930
2671.83	993
2673.65	1018
2675.48	1070.5
2677.3	1094.5
2679.12	1082
2680.95	1105
2682.77	1113.5
2684.59	1080.5
2686.41	1063
2688.23	1029.5
2690.05	987
2691.87	970
2693.69	950.5
2695.51	913.5
2697.33	883.5
2699.14	884
2700.96	875.5
2702.78	873.5
2704.59	820.5
2706.41	801.5
2708.22	803
2710.04	795
2711.85	784.5
2713.66	775.5
2715.48	776
2717.29	768
2719.1	748
2720.91	752
2722.72	738
2724.53	726
2726.34	728
2728.15	710
2729.96	690.5
2731.77	710
2733.58	695
2735.38	687
2737.19	696
2738.99	667
2740.8	667.5
2742.61	674.5
2744.41	677.5
2746.21	665.5
2748.02	672.5
2749.82	678
2751.62	671.5
2753.42	679
2755.23	660.5
2757.03	684
2758.83	672
2760.63	671
2762.43	682
2764.23	652.5
2766.02	682
2767.82	671.5
2769.62	662
2771.42	667.5
2773.21	668.5
2775.01	663
2776.8	665
2778.6	667
2780.39	645
2782.19	653.5
2783.98	653.5
2785.77	676.5
2787.56	653
2789.35	669
2791.15	660
2792.94	658.5
2794.73	650
2796.52	656
2798.31	654
2800.09	646
2801.88	645.5
2803.67	656
2805.46	652
2807.24	653
2809.03	657
2810.82	659
2812.6	649.5
2814.39	650
2816.17	651
2817.95	645.5
2819.74	635
2821.52	658.5
2823.3	646
2825.08	650
2826.86	630
2828.64	652
2830.42	646
2832.2	645.5
2833.98	632.5
2835.76	633
2837.54	639
2839.32	641.5
2841.09	628.5
2842.87	640
2844.65	645.5
2846.42	649.5
2848.2	620
2849.97	637.5
2851.75	632
2853.52	644
2855.29	628
2857.06	648
2858.84	646
2860.61	643
2862.38	654.5
2864.15	648
2865.92	633
2867.69	635.5
2869.46	634
2871.23	636.5
2873	639
2874.76	630
2876.53	623.5
2878.3	639.5
2880.06	636
2881.83	633.5
2883.59	649
2885.36	625
2887.12	636
2888.89	626
2890.65	630.5
2892.41	635
2894.17	630
2895.93	624.5
2897.7	630.5
2899.46	640
2901.22	622
2902.98	628
2904.73	633
2906.49	631.5
2908.25	630
2910.01	626
2911.77	628
2913.52	609
2915.28	622
2917.04	625.5
2918.79	638
2920.54	630
2922.3	632.5
2924.05	629
2925.81	639
2927.56	610.5
2929.31	616
2931.06	625.5
2932.81	623.5
2934.56	606.5
2936.31	628
2938.06	612.5
2939.81	615
2941.56	631.5
2943.31	617.5
2945.06	608
2946.81	622
2948.55	628.5
2950.3	620
2952.04	628
2953.79	599.5
2955.53	592
2957.28	613
2959.02	620
2960.77	619.5
2962.51	613.5
2964.25	613
2965.99	613.5
2967.73	612
2969.48	610.5
2971.22	596
2972.96	581
2974.7	610
2976.43	622
2978.17	612
2979.91	588
2981.65	596
2983.39	627
2985.12	595.5
2986.86	608.5
2988.59	605
2990.33	596
2992.06	588
2993.8	597.5
2995.53	614
2997.27	599
2999	605