File: Data/Blue_20x5_25%/2D_position.txt
#Acq. time (s)=	20
#Accumulations=	5
#Range (cm-¹)=	1000...3000
#Windows=	1
#Auto scanning=	Off
#Autofocus=	At all pixels
#SWIFT=	Off
#Macrospot=	Off
#AutoExposure=	Off
#Spike filter=	Multiple accum.
#Delay time (s)=	0
#Binning=	1
#Readout mode=	Signal
#DeNoise=	Off
#ICS correction=	Off
#Dark correction=	Off
#Inst. Process=	Off
#Detector Gain=	Best Dynamic Range
#Detector ADC=	45 kHz
#Detector temperature (°C)=	-60.1
#Instrument=	LabRAM HR Evol
#Detector=	Syncerity OE
#Objective=	x100_VIS_LWD
#Grating=	300 (600nm)
#ND Filter=	25%
#Laser=	488nm_Edge
#Hole=	199.981
#Range=	Visible
#StageXY=	75x50mm Scan+
#StageZ=	Z motor
#X (µm)=	0
#Y (µm)=	0
#Z (µm)=	-4238.55
#Full time(hh:mm)=	25:17
#Project=
#Sample=
#Site=
#Title=	operando_blue_25%_20x5
#Remark=
#Date=	02.10.2024 11:24
#Generated=	03.10.2024 12:41:31
#AxisType[0]=Spectr
#AxisUnit[0]=1/cm
#AxisType[1]=Time
#AxisUnit[1]=sec
0	2732.32
320.151	2732.32
640.301	2732.32
960.452	2732.32
1280.6	2732.32
1600.75	2732.32
1920.9	2732.32
2241.05	2732.32
2561.21	2732.32
2881.36	2732.32
3201.51	2732.32
3521.66	2732.32
3841.81	2732.32
4161.96	2732.32
4482.11	2728.95
4802.26	2728.95
5122.41	2728.95
5442.56	2725.58
5762.71	2728.95
6082.86	2732.32
6403.01	2732.32
6723.16	2732.32
7043.31	2732.32
7363.47	2732.32
7683.62	2732.32
8003.77	2732.32
8323.92	2732.32
8644.07	2732.32
8964.22	2732.32
9284.37	2732.32
9604.52	2732.32
9924.67	2732.32
10244.8	2735.68
10565	2732.32
10885.1	2735.68
11205.3	2732.32
11525.4	2735.68
11845.6	2735.68
12165.7	2735.68
12485.9	2735.68
12806	2735.68
13126.2	2735.68
13446.3	2732.32
13766.5	2735.68
14086.6	2735.68
14406.8	2732.32
14726.9	2732.32
15047.1	2728.95
15367.2	2728.95
15687.4	2728.95
16007.5	2732.32
16327.7	2735.68
16647.8	2735.68
16968	2735.68
17288.1	2735.68
17608.3	2735.68
17928.4	2735.68
18248.6	2735.68
18568.7	2735.68
18888.9	2735.68
19209	2735.68
19529.2	2735.68
19849.3	2735.68
20169.5	2735.68
20489.6	2735.68
20809.8	2735.68
21129.9	2735.68
21450.1	2735.68
21770.2	2735.68
22090.4	2735.68
22410.5	2735.68
22730.7	2735.68
23050.8	2735.68
23371	2739.04
23691.1	2735.68
24011.3	2735.68
24331.4	2732.32
24651.6	2732.32
24971.8	2728.95
25291.9	2732.32
25612.1	2735.68
25932.2	2735.68
26252.4	2735.68
26572.5	2735.68
26892.7	2735.68
27212.8	2735.68
27533	2739.04
27853.1	2735.68
28173.3	2735.68
28493.4	2739.04
28813.6	2735.68
29133.7	2735.68
29453.9	2735.68
29774	2735.68
30094.2	2732.32
30414.3	2695.21
30734.5	2678.29
31054.6	2630.74
31374.8	2617.11
31694.9	2617.11
32015.1	2617.11
32335.2	2617.11
32655.4	2617.11
32975.5	2617.11
33295.7	2617.11
33615.8	2617.11
33936	2630.74
34256.1	2715.47
34576.3	2728.95
34896.4	2732.32
35216.6	2732.32
35536.7	2732.32
35856.9	2735.68
36177	2728.95
36497.2	2722.21
36817.3	2705.34
37137.5	2691.83
37457.6	2688.44
37777.8	2691.83
38097.9	2678.29
38418.1	2637.55
38738.2	2617.11
39058.4	2728.95
39378.5	2735.68
39698.7	2735.68
40018.8	2728.95
40339	2722.21
40659.1	2722.21
40979.3	2708.72
41299.4	2715.47
41619.6	2725.58
41939.7	2725.58
42259.9	2722.21
42580	2701.97
42900.2	2691.83
43220.3	2674.9
43540.5	2651.15
43860.6	2617.11
44180.8	2617.11
44500.9	2617.11
44821.1	2732.32
45141.2	2728.95
45461.4	2732.32
45781.5	2732.32
46101.7	2732.32
46421.8	2732.32
46742	2732.32
47062.1	2732.32
47382.3	2732.32
47702.4	2732.32
48022.6	2732.32
48342.8	2732.32
48662.9	2735.68
48983.1	2732.32
49303.2	2732.32
49623.4	2728.95
49943.5	2725.58
50263.7	2701.97
50583.8	2691.83
50904	2681.67
51224.1	2664.73
51544.3	2674.9
51864.4	2668.12
52184.6	2661.34
52504.7	2664.73
52824.9	2671.51
53145	2644.35
53465.2	2617.11
53785.3	2617.11
54105.5	2617.11
54425.6	2617.11
54745.8	2617.11
55065.9	2644.35
55386.1	2732.32
55706.2	2732.32
56026.4	2732.32
56346.5	2732.32
56666.7	2732.32
56986.8	2732.32
57307	2732.32
57627.1	2732.32
57947.3	2732.32
58267.4	2732.32
58587.6	2732.32
58907.7	2732.32
59227.9	2735.68
59548	2732.32
59868.2	2732.32
60188.3	2735.68
60508.5	2732.32
60828.6	2735.68
61148.8	2732.32
61468.9	2732.32
61789.1	2725.58
62109.2	2722.21
62429.4	2695.21
62749.5	2725.58
63069.7	2718.84
63389.8	2725.58
63710	2728.95
64030.1	2728.95
64350.3	2728.95
64670.4	2728.95
64990.6	2728.95
65310.7	2732.32
65630.9	2732.32
65951	2732.32
66271.2	2732.32
66591.3	2732.32
66911.5	2732.32
67231.6	2732.32
67551.8	2732.32
67871.9	2732.32
68192.1	2732.32
68512.2	2732.32
68832.4	2732.32
69152.5	2732.32
69472.7	2732.32
69792.8	2732.32
70113	2732.32
70433.1	2732.32
70753.3	2732.32
71073.4	2732.32
71393.6	2732.32
71713.8	2732.32
72033.9	2732.32
72354	2732.32
72674.2	2732.32
72994.4	2732.32
73314.5	2728.95
73634.6	2728.95
73954.8	2728.95
74275	2728.95
74595.1	2732.32
74915.3	2732.32
75235.4	2728.95
75555.6	2728.95
75875.7	2732.32
76195.9	2728.95
76516	2728.95
76836.2	2732.32
77156.3	2732.32
77476.5	2732.32
77796.6	2732.32
78116.8	2732.32
78436.9	2732.32
78757.1	2732.32
79077.2	2732.32
79397.4	2732.32
79717.5	2732.32
80037.7	2732.32
80357.8	2732.32
80678	2732.32
80998.1	2732.32
81318.3	2732.32
81638.4	2732.32
81958.6	2732.32
82278.7	2732.32
82598.9	2732.32
82919	2728.95
83239.2	2728.95
83559.3	2728.95
83879.5	2725.58
84199.6	2732.32
84519.8	2728.95
84839.9	2728.95
85160.1	2732.32
85480.2	2732.32
85800.4	2732.32
86120.5	2732.32
86440.7	2728.95
86760.8	2725.58
87081	2732.32
87401.1	2732.32
87721.3	2732.32
88041.4	2732.32
88361.6	2732.32
88681.7	2732.32
89001.9	2732.32
89322	2735.68
89642.2	2725.58