File: Data/Blue_20x5_25%/D_position.txt
#Acq. time (s)=	20
#Accumulations=	5
#Range (cm-¹)=	1000...3000
#Windows=	1
#Auto scanning=	Off
#Autofocus=	At all pixels
#SWIFT=	Off
#Macrospot=	Off
#AutoExposure=	Off
#Spike filter=	Multiple accum.
#Delay time (s)=	0
#Binning=	1
#Readout mode=	Signal
#DeNoise=	Off
#ICS correction=	Off
#Dark correction=	Off
#Inst. Process=	Off
#Detector Gain=	Best Dynamic Range
#Detector ADC=	45 kHz
#Detector temperature (°C)=	-60.1
#Instrument=	LabRAM HR Evol
#Detector=	Syncerity OE
#Objective=	x100_VIS_LWD
#Grating=	300 (600nm)
#ND Filter=	25%
#Laser=	488nm_Edge
#Hole=	199.981
#Range=	Visible
#StageXY=	75x50mm Scan+
#StageZ=	Z motor
#X (µm)=	0
#Y (µm)=	0
#Z (µm)=	-4238.55
#Full time(hh:mm)=	25:17
#Project=
#Sample=
#Site=
#Title=	operando_blue_25%_20x5
#Remark=
#Date=	02.10.2024 11:24
#Generated=	03.10.2024 13:09:33
#AxisType[0]=Spectr
#AxisUnit[0]=1/cm
#AxisType[1]=Time
#AxisUnit[1]=sec
0	1356.23
320.151	1352.31
640.301	1352.31
960.452	1352.31
1280.6	1352.31
1600.75	1352.31
1920.9	1352.31
2241.05	1352.31
2561.21	1352.31
2881.36	1352.31
3201.51	1352.31
3521.66	1352.31
3841.81	1352.31
4161.96	1352.31
4482.11	1352.31
4802.26	1352.31
5122.41	1352.31
5442.56	1352.31
5762.71	1352.31
6082.86	1352.31
6403.01	1352.31
6723.16	1352.31
7043.31	1352.31
7363.47	1352.31
7683.62	1352.31
8003.77	1352.31
8323.92	1348.39
8644.07	1352.31
8964.22	1352.31
9284.37	1352.31
9604.52	1356.23
9924.67	1352.31
10244.8	1356.23
10565	1352.31
10885.1	1352.31
11205.3	1352.31
11525.4	1352.31
11845.6	1356.23
12165.7	1356.23
12485.9	1348.39
12806	1356.23
13126.2	1352.31
13446.3	1356.23
13766.5	1356.23
14086.6	1352.31
14406.8	1352.31
14726.9	1356.23
15047.1	1356.23
15367.2	1356.23
15687.4	1356.23
16007.5	1356.23
16327.7	1356.23
16647.8	1356.23
16968	1356.23
17288.1	1360.14
17608.3	1352.31
17928.4	1356.23
18248.6	1356.23
18568.7	1356.23
18888.9	1356.23
19209	1356.23
19529.2	1356.23
19849.3	1356.23
20169.5	1356.23
20489.6	1356.23
20809.8	1356.23
21129.9	1356.23
21450.1	1360.14
21770.2	1356.23
22090.4	1356.23
22410.5	1360.14
22730.7	1367.97
23050.8	1364.06
23371	1356.23
23691.1	1356.23
24011.3	1360.14
24331.4	1364.06
24651.6	1418.67
24971.8	1418.67
25291.9	1418.67
25612.1	1418.67
25932.2	1414.78
26252.4	1356.23
26572.5	1414.78
26892.7	1364.06
27212.8	1364.06
27533	1364.06
27853.1	1356.23
28173.3	1360.14
28493.4	1364.06
28813.6	1356.23
29133.7	1356.23
29453.9	1356.23
29774	1360.14
30094.2	1360.14
30414.3	1360.14
30734.5	1356.23
31054.6	1418.67
31374.8	1418.67
31694.9	1418.67
32015.1	1418.67
32335.2	1418.67
32655.4	1418.67
32975.5	1418.67
33295.7	1414.78
33615.8	1418.67
33936	1418.67
34256.1	1418.67
34576.3	1418.67
34896.4	1418.67
35216.6	1418.67
35536.7	1418.67
35856.9	1414.78
36177	1418.67
36497.2	1418.67
36817.3	1418.67
37137.5	1418.67
37457.6	1414.78
37777.8	1418.67
38097.9	1418.67
38418.1	1418.67
38738.2	1320.92
39058.4	1418.67
39378.5	1418.67
39698.7	1418.67
40018.8	1418.67
40339	1418.67
40659.1	1418.67
40979.3	1418.67
41299.4	1418.67
41619.6	1418.67
41939.7	1418.67
42259.9	1418.67
42580	1418.67
42900.2	1414.78
43220.3	1418.67
43540.5	1418.67
43860.6	1418.67
44180.8	1418.67
44500.9	1418.67
44821.1	1418.67
45141.2	1414.78
45461.4	1418.67
45781.5	1418.67
46101.7	1414.78
46421.8	1418.67
46742	1414.78
47062.1	1418.67
47382.3	1418.67
47702.4	1418.67
48022.6	1418.67
48342.8	1418.67
48662.9	1418.67
48983.1	1418.67
49303.2	1414.78
49623.4	1418.67
49943.5	1414.78
50263.7	1414.78
50583.8	1418.67
50904	1418.67
51224.1	1418.67
51544.3	1414.78
51864.4	1418.67
52184.6	1418.67
52504.7	1418.67
52824.9	1418.67
53145	1418.67
53465.2	1414.78
53785.3	1418.67
54105.5	1418.67
54425.6	1418.67
54745.8	1418.67
55065.9	1418.67
55386.1	1414.78
55706.2	1414.78
56026.4	1418.67
56346.5	1414.78
56666.7	1418.67
56986.8	1414.78
57307	1418.67
57627.1	1414.78
57947.3	1418.67
58267.4	1418.67
58587.6	1418.67
58907.7	1414.78
59227.9	1418.67
59548	1418.67
59868.2	1418.67
60188.3	1418.67
60508.5	1418.67
60828.6	1414.78
61148.8	1414.78
61468.9	1418.67
61789.1	1414.78
62109.2	1418.67
62429.4	1418.67
62749.5	1418.67
63069.7	1418.67
63389.8	1418.67
63710	1418.67
64030.1	1418.67
64350.3	1418.67
64670.4	1418.67
64990.6	1418.67
65310.7	1418.67
65630.9	1414.78
65951	1418.67
66271.2	1418.67
66591.3	1418.67
66911.5	1418.67
67231.6	1418.67
67551.8	1418.67
67871.9	1418.67
68192.1	1414.78
68512.2	1410.89
68832.4	1414.78
69152.5	1418.67
69472.7	1418.67
69792.8	1414.78
70113	1418.67
70433.1	1418.67
70753.3	1418.67
71073.4	1356.23
71393.6	1364.06
71713.8	1364.06
72033.9	1356.23
72354	1356.23
72674.2	1356.23
72994.4	1344.47
73314.5	1414.78
73634.6	1418.67
73954.8	1414.78
74275	1418.67
74595.1	1418.67
74915.3	1418.67
75235.4	1418.67
75555.6	1356.23
75875.7	1360.14
76195.9	1356.23
76516	1352.31
76836.2	1348.39
77156.3	1364.06
77476.5	1356.23
77796.6	1348.39
78116.8	1356.23
78436.9	1348.39
78757.1	1348.39
79077.2	1348.39
79397.4	1356.23
79717.5	1352.31
80037.7	1344.47
80357.8	1344.47
80678	1348.39
80998.1	1348.39
81318.3	1348.39
81638.4	1348.39
81958.6	1348.39
82278.7	1356.23
82598.9	1414.78
82919	1356.23
83239.2	1348.39
83559.3	1418.67
83879.5	1414.78
84199.6	1344.47
84519.8	1352.31
84839.9	1348.39
85160.1	1356.23
85480.2	1352.31
85800.4	1324.85
86120.5	1313.05
86440.7	1305.18
86760.8	1305.18
87081	1348.39
87401.1	1344.47
87721.3	1340.55
88041.4	1344.47
88361.6	1344.47
88681.7	1344.47
89001.9	1336.63
89322	1344.47
89642.2	1309.12