File: Data/Blue_20x5_25%/G_position.txt
#Acq. time (s)=	20
#Accumulations=	5
#Range (cm-¹)=	1000...3000
#Windows=	1
#Auto scanning=	Off
#Autofocus=	At all pixels
#SWIFT=	Off
#Macrospot=	Off
#AutoExposure=	Off
#Spike filter=	Multiple accum.
#Delay time (s)=	0
#Binning=	1
#Readout mode=	Signal
#DeNoise=	Off
#ICS correction=	Off
#Dark correction=	Off
#Inst. Process=	Off
#Detector Gain=	Best Dynamic Range
#Detector ADC=	45 kHz
#Detector temperature (°C)=	-60.1
#Instrument=	LabRAM HR Evol
#Detector=	Syncerity OE
#Objective=	x100_VIS_LWD
#Grating=	300 (600nm)
#ND Filter=	25%
#Laser=	488nm_Edge
#Hole=	199.981
#Range=	Visible
#StageXY=	75x50mm Scan+
#StageZ=	Z motor
#X (µm)=	0
#Y (µm)=	0
#Z (µm)=	-4238.55
#Full time(hh:mm)=	25:17
#Project=
#Sample=
#Site=
#Title=	operando_blue_25%_20x5
#Remark=
#Date=	02.10.2024 11:24
#Generated=	03.10.2024 12:41:31
#AxisType[0]=Spectr
#AxisUnit[0]=1/cm
#AxisType[1]=Time
#AxisUnit[1]=sec
0	1580.65
320.151	1580.65
640.301	1580.65
960.452	1580.65
1280.6	1580.65
1600.75	1580.65
1920.9	1580.65
2241.05	1580.65
2561.21	1580.65
2881.36	1580.65
3201.51	1580.65
3521.66	1580.65
3841.81	1576.83
4161.96	1576.83
4482.11	1580.65
4802.26	1584.48
5122.41	1584.48
5442.56	1584.48
5762.71	1584.48
6082.86	1580.65
6403.01	1576.83
6723.16	1576.83
7043.31	1576.83
7363.47	1576.83
7683.62	1576.83
8003.77	1576.83
8323.92	1580.65
8644.07	1580.65
8964.22	1580.65
9284.37	1580.65
9604.52	1580.65
9924.67	1580.65
10244.8	1580.65
10565	1580.65
10885.1	1580.65
11205.3	1580.65
11525.4	1580.65
11845.6	1580.65
12165.7	1580.65
12485.9	1580.65
12806	1580.65
13126.2	1580.65
13446.3	1580.65
13766.5	1580.65
14086.6	1580.65
14406.8	1584.48
14726.9	1584.48
15047.1	1588.3
15367.2	1584.48
15687.4	1584.48
16007.5	1584.48
16327.7	1580.65
16647.8	1580.65
16968	1580.65
17288.1	1580.65
17608.3	1580.65
17928.4	1580.65
18248.6	1580.65
18568.7	1580.65
18888.9	1580.65
19209	1580.65
19529.2	1584.48
19849.3	1584.48
20169.5	1584.48
20489.6	1584.48
20809.8	1584.48
21129.9	1584.48
21450.1	1584.48
21770.2	1584.48
22090.4	1584.48
22410.5	1584.48
22730.7	1584.48
23050.8	1584.48
23371	1584.48
23691.1	1580.65
24011.3	1584.48
24331.4	1588.3
24651.6	1588.3
24971.8	1588.3
25291.9	1588.3
25612.1	1588.3
25932.2	1584.48
26252.4	1580.65
26572.5	1584.48
26892.7	1584.48
27212.8	1584.48
27533	1584.48
27853.1	1584.48
28173.3	1584.48
28493.4	1584.48
28813.6	1584.48
29133.7	1584.48
29453.9	1584.48
29774	1580.65
30094.2	1580.65
30414.3	1576.83
30734.5	1576.83
31054.6	1576.83
31374.8	1573
31694.9	1573
32015.1	1573
32335.2	1573
32655.4	1573
32975.5	1573
33295.7	1573
33615.8	1573
33936	1580.65
34256.1	1580.65
34576.3	1584.48
34896.4	1584.48
35216.6	1584.48
35536.7	1580.65
35856.9	1576.83
36177	1576.83
36497.2	1576.83
36817.3	1576.83
37137.5	1576.83
37457.6	1576.83
37777.8	1576.83
38097.9	1576.83
38418.1	1573
38738.2	1503.87
39058.4	1573
39378.5	1573
39698.7	1569.18
40018.8	1565.35
40339	1565.35
40659.1	1561.52
40979.3	1557.68
41299.4	1557.68
41619.6	1561.52
41939.7	1561.52
42259.9	1557.68
42580	1550.01
42900.2	1553.85
43220.3	1553.85
43540.5	1553.85
43860.6	1534.66
44180.8	1503.87
44500.9	1503.87
44821.1	1576.83
45141.2	1580.65
45461.4	1576.83
45781.5	1576.83
46101.7	1576.83
46421.8	1573
46742	1573
47062.1	1573
47382.3	1573
47702.4	1573
48022.6	1573
48342.8	1573
48662.9	1573
48983.1	1573
49303.2	1573
49623.4	1573
49943.5	1569.18
50263.7	1569.18
50583.8	1569.18
50904	1565.35
51224.1	1565.35
51544.3	1565.35
51864.4	1565.35
52184.6	1565.35
52504.7	1565.35
52824.9	1569.18
53145	1569.18
53465.2	1557.68
53785.3	1550.01
54105.5	1534.66
54425.6	1507.72
54745.8	1503.87
55065.9	1573
55386.1	1573
55706.2	1569.18
56026.4	1569.18
56346.5	1573
56666.7	1573
56986.8	1573
57307	1573
57627.1	1573
57947.3	1573
58267.4	1573
58587.6	1573
58907.7	1573
59227.9	1573
59548	1569.18
59868.2	1569.18
60188.3	1569.18
60508.5	1565.35
60828.6	1565.35
61148.8	1565.35
61468.9	1565.35
61789.1	1565.35
62109.2	1561.52
62429.4	1557.68
62749.5	1565.35
63069.7	1565.35
63389.8	1573
63710	1576.83
64030.1	1576.83
64350.3	1580.65
64670.4	1576.83
64990.6	1576.83
65310.7	1576.83
65630.9	1576.83
65951	1576.83
66271.2	1576.83
66591.3	1576.83
66911.5	1576.83
67231.6	1576.83
67551.8	1576.83
67871.9	1576.83
68192.1	1576.83
68512.2	1576.83
68832.4	1576.83
69152.5	1576.83
69472.7	1576.83
69792.8	1576.83
70113	1576.83
70433.1	1573
70753.3	1573
71073.4	1569.18
71393.6	1565.35
71713.8	1565.35
72033.9	1561.52
72354	1557.68
72674.2	1557.68
72994.4	1557.68
73314.5	1565.35
73634.6	1569.18
73954.8	1561.52
74275	1557.68
74595.1	1550.01
74915.3	1542.34
75235.4	1534.66
75555.6	1530.82
75875.7	1526.97
76195.9	1526.97
76516	1526.97
76836.2	1526.97
77156.3	1538.5
77476.5	1553.85
77796.6	1565.35
78116.8	1565.35
78436.9	1569.18
78757.1	1569.18
79077.2	1569.18
79397.4	1569.18
79717.5	1569.18
80037.7	1565.35
80357.8	1565.35
80678	1565.35
80998.1	1561.52
81318.3	1561.52
81638.4	1557.68
81958.6	1557.68
82278.7	1550.01
82598.9	1550.01
82919	1553.85
83239.2	1553.85
83559.3	1534.66
83879.5	1503.87
84199.6	1546.18
84519.8	1557.68
84839.9	1557.68
85160.1	1542.34
85480.2	1526.97
85800.4	1507.72
86120.5	1503.87
86440.7	1503.87
86760.8	1503.87
87081	1526.97
87401.1	1550.01
87721.3	1561.52
88041.4	1561.52
88361.6	1561.52
88681.7	1557.68
89001.9	1546.18
89322	1530.82
89642.2	1515.43